2024-06-07 01:37:18,402 - INFO - Started Scraping URL -> 1/2
2024-06-07 01:37:23,454 - INFO - Getting Foreclosure Dates For -> 1/2
2024-06-07 01:37:54,163 - ERROR - Error in => https://escambia.realforeclose.com/index.cfm?resetcfcobjs=1 | Error: main() missing 3 required positional arguments: 'driver', 'domain_name', and 'foreclosure_dates'
Traceback (most recent call last):
  File "C:\Users\MAK\Documents\GitHub\scraper_BOT-1_v3\scraper_BOT-1_v3.1.1.1-test.py", line 454, in <module>
    rows_to_input_in_csv = main()
                           ^^^^^^
TypeError: main() missing 3 required positional arguments: 'driver', 'domain_name', and 'foreclosure_dates'
2024-06-07 01:37:54,164 - INFO - Started Scraping URL -> 2/2
2024-06-07 01:37:59,217 - INFO - Getting Foreclosure Dates For -> 2/2
2024-06-07 01:39:18,553 - ERROR - Error in => https://escambia.realtaxdeed.com/index.cfm?resetcfcobjs=1 | Error: main() missing 3 required positional arguments: 'driver', 'domain_name', and 'foreclosure_dates'
Traceback (most recent call last):
  File "C:\Users\MAK\Documents\GitHub\scraper_BOT-1_v3\scraper_BOT-1_v3.1.1.1-test.py", line 454, in <module>
    rows_to_input_in_csv = main()
                           ^^^^^^
TypeError: main() missing 3 required positional arguments: 'driver', 'domain_name', and 'foreclosure_dates'
2024-06-07 01:40:47,968 - INFO - Started Scraping URL -> 1/2
2024-06-07 01:40:51,277 - INFO - Getting Foreclosure Dates For -> 1/2
2024-06-07 01:41:44,135 - INFO - Started Scraping URL -> 2/2
2024-06-07 01:41:48,201 - WARNING - Retrying (Retry(total=2, connect=None, read=None, redirect=None, status=None)) after connection broken by 'NewConnectionError('<urllib3.connection.HTTPConnection object at 0x0000021B3B26C250>: Failed to establish a new connection: [WinError 10061] No connection could be made because the target machine actively refused it')': /session/dce763bb35de7c45b3354688b40c176d/url
2024-06-07 01:41:52,225 - WARNING - Retrying (Retry(total=1, connect=None, read=None, redirect=None, status=None)) after connection broken by 'NewConnectionError('<urllib3.connection.HTTPConnection object at 0x0000021B3B6FEC10>: Failed to establish a new connection: [WinError 10061] No connection could be made because the target machine actively refused it')': /session/dce763bb35de7c45b3354688b40c176d/url
2024-06-07 01:41:56,245 - WARNING - Retrying (Retry(total=0, connect=None, read=None, redirect=None, status=None)) after connection broken by 'NewConnectionError('<urllib3.connection.HTTPConnection object at 0x0000021B3B6FE5D0>: Failed to establish a new connection: [WinError 10061] No connection could be made because the target machine actively refused it')': /session/dce763bb35de7c45b3354688b40c176d/url
2024-06-07 01:42:00,274 - ERROR - Error in => https://escambia.realtaxdeed.com/index.cfm?resetcfcobjs=1 | Error: HTTPConnectionPool(host='localhost', port=61887): Max retries exceeded with url: /session/dce763bb35de7c45b3354688b40c176d/url (Caused by NewConnectionError('<urllib3.connection.HTTPConnection object at 0x0000021B3B6FFA10>: Failed to establish a new connection: [WinError 10061] No connection could be made because the target machine actively refused it'))
Traceback (most recent call last):
  File "C:\Users\MAK\Documents\GitHub\scraper_BOT-1_v3\venv\Lib\site-packages\urllib3\connection.py", line 174, in _new_conn
    conn = connection.create_connection(
           ^^^^^^^^^^^^^^^^^^^^^^^^^^^^^
  File "C:\Users\MAK\Documents\GitHub\scraper_BOT-1_v3\venv\Lib\site-packages\urllib3\util\connection.py", line 95, in create_connection
    raise err
  File "C:\Users\MAK\Documents\GitHub\scraper_BOT-1_v3\venv\Lib\site-packages\urllib3\util\connection.py", line 85, in create_connection
    sock.connect(sa)
ConnectionRefusedError: [WinError 10061] No connection could be made because the target machine actively refused it

During handling of the above exception, another exception occurred:

Traceback (most recent call last):
  File "C:\Users\MAK\Documents\GitHub\scraper_BOT-1_v3\venv\Lib\site-packages\urllib3\connectionpool.py", line 715, in urlopen
    httplib_response = self._make_request(
                       ^^^^^^^^^^^^^^^^^^^
  File "C:\Users\MAK\Documents\GitHub\scraper_BOT-1_v3\venv\Lib\site-packages\urllib3\connectionpool.py", line 416, in _make_request
    conn.request(method, url, **httplib_request_kw)
  File "C:\Users\MAK\Documents\GitHub\scraper_BOT-1_v3\venv\Lib\site-packages\urllib3\connection.py", line 244, in request
    super(HTTPConnection, self).request(method, url, body=body, headers=headers)
  File "C:\Users\MAK\AppData\Local\Programs\Python\Python311\Lib\http\client.py", line 1286, in request
    self._send_request(method, url, body, headers, encode_chunked)
  File "C:\Users\MAK\AppData\Local\Programs\Python\Python311\Lib\http\client.py", line 1332, in _send_request
    self.endheaders(body, encode_chunked=encode_chunked)
  File "C:\Users\MAK\AppData\Local\Programs\Python\Python311\Lib\http\client.py", line 1281, in endheaders
    self._send_output(message_body, encode_chunked=encode_chunked)
  File "C:\Users\MAK\AppData\Local\Programs\Python\Python311\Lib\http\client.py", line 1041, in _send_output
    self.send(msg)
  File "C:\Users\MAK\AppData\Local\Programs\Python\Python311\Lib\http\client.py", line 979, in send
    self.connect()
  File "C:\Users\MAK\Documents\GitHub\scraper_BOT-1_v3\venv\Lib\site-packages\urllib3\connection.py", line 205, in connect
    conn = self._new_conn()
           ^^^^^^^^^^^^^^^^
  File "C:\Users\MAK\Documents\GitHub\scraper_BOT-1_v3\venv\Lib\site-packages\urllib3\connection.py", line 186, in _new_conn
    raise NewConnectionError(
urllib3.exceptions.NewConnectionError: <urllib3.connection.HTTPConnection object at 0x0000021B3B6FFA10>: Failed to establish a new connection: [WinError 10061] No connection could be made because the target machine actively refused it

During handling of the above exception, another exception occurred:

Traceback (most recent call last):
  File "C:\Users\MAK\Documents\GitHub\scraper_BOT-1_v3\scraper_BOT-1_v3.1.1.1-test.py", line 422, in <module>
    driver.get(data['modified_url'])
  File "C:\Users\MAK\Documents\GitHub\scraper_BOT-1_v3\venv\Lib\site-packages\selenium\webdriver\remote\webdriver.py", line 354, in get
    self.execute(Command.GET, {"url": url})
  File "C:\Users\MAK\Documents\GitHub\scraper_BOT-1_v3\venv\Lib\site-packages\selenium\webdriver\remote\webdriver.py", line 343, in execute
    response = self.command_executor.execute(driver_command, params)
               ^^^^^^^^^^^^^^^^^^^^^^^^^^^^^^^^^^^^^^^^^^^^^^^^^^^^^
  File "C:\Users\MAK\Documents\GitHub\scraper_BOT-1_v3\venv\Lib\site-packages\selenium\webdriver\remote\remote_connection.py", line 291, in execute
    return self._request(command_info[0], url, body=data)
           ^^^^^^^^^^^^^^^^^^^^^^^^^^^^^^^^^^^^^^^^^^^^^^
  File "C:\Users\MAK\Documents\GitHub\scraper_BOT-1_v3\venv\Lib\site-packages\selenium\webdriver\remote\remote_connection.py", line 312, in _request
    response = self._conn.request(method, url, body=body, headers=headers)
               ^^^^^^^^^^^^^^^^^^^^^^^^^^^^^^^^^^^^^^^^^^^^^^^^^^^^^^^^^^^
  File "C:\Users\MAK\Documents\GitHub\scraper_BOT-1_v3\venv\Lib\site-packages\urllib3\request.py", line 81, in request
    return self.request_encode_body(
           ^^^^^^^^^^^^^^^^^^^^^^^^^
  File "C:\Users\MAK\Documents\GitHub\scraper_BOT-1_v3\venv\Lib\site-packages\urllib3\request.py", line 173, in request_encode_body
    return self.urlopen(method, url, **extra_kw)
           ^^^^^^^^^^^^^^^^^^^^^^^^^^^^^^^^^^^^^
  File "C:\Users\MAK\Documents\GitHub\scraper_BOT-1_v3\venv\Lib\site-packages\urllib3\poolmanager.py", line 376, in urlopen
    response = conn.urlopen(method, u.request_uri, **kw)
               ^^^^^^^^^^^^^^^^^^^^^^^^^^^^^^^^^^^^^^^^^
  File "C:\Users\MAK\Documents\GitHub\scraper_BOT-1_v3\venv\Lib\site-packages\urllib3\connectionpool.py", line 827, in urlopen
    return self.urlopen(
           ^^^^^^^^^^^^^
  File "C:\Users\MAK\Documents\GitHub\scraper_BOT-1_v3\venv\Lib\site-packages\urllib3\connectionpool.py", line 827, in urlopen
    return self.urlopen(
           ^^^^^^^^^^^^^
  File "C:\Users\MAK\Documents\GitHub\scraper_BOT-1_v3\venv\Lib\site-packages\urllib3\connectionpool.py", line 827, in urlopen
    return self.urlopen(
           ^^^^^^^^^^^^^
  File "C:\Users\MAK\Documents\GitHub\scraper_BOT-1_v3\venv\Lib\site-packages\urllib3\connectionpool.py", line 799, in urlopen
    retries = retries.increment(
              ^^^^^^^^^^^^^^^^^^
  File "C:\Users\MAK\Documents\GitHub\scraper_BOT-1_v3\venv\Lib\site-packages\urllib3\util\retry.py", line 592, in increment
    raise MaxRetryError(_pool, url, error or ResponseError(cause))
urllib3.exceptions.MaxRetryError: HTTPConnectionPool(host='localhost', port=61887): Max retries exceeded with url: /session/dce763bb35de7c45b3354688b40c176d/url (Caused by NewConnectionError('<urllib3.connection.HTTPConnection object at 0x0000021B3B6FFA10>: Failed to establish a new connection: [WinError 10061] No connection could be made because the target machine actively refused it'))
2024-06-07 01:58:25,714 - INFO - Started Scraping URL -> 1/2
2024-06-07 01:58:31,068 - INFO - Getting Foreclosure Dates For -> 1/2
2024-06-07 01:58:58,250 - WARNING - Retrying (Retry(total=2, connect=None, read=None, redirect=None, status=None)) after connection broken by 'NewConnectionError('<urllib3.connection.HTTPConnection object at 0x00000219F5FEB490>: Failed to establish a new connection: [WinError 10061] No connection could be made because the target machine actively refused it')': /session/4fbded65cbaa46c2e9b54babcde4071d/elements
2024-06-07 01:59:02,698 - WARNING - Retrying (Retry(total=1, connect=None, read=None, redirect=None, status=None)) after connection broken by 'NewConnectionError('<urllib3.connection.HTTPConnection object at 0x00000219F523A550>: Failed to establish a new connection: [WinError 10061] No connection could be made because the target machine actively refused it')': /session/4fbded65cbaa46c2e9b54babcde4071d/elements
2024-06-07 01:59:06,924 - WARNING - Retrying (Retry(total=0, connect=None, read=None, redirect=None, status=None)) after connection broken by 'NewConnectionError('<urllib3.connection.HTTPConnection object at 0x00000219F6470150>: Failed to establish a new connection: [WinError 10061] No connection could be made because the target machine actively refused it')': /session/4fbded65cbaa46c2e9b54babcde4071d/elements
2024-06-07 01:59:15,305 - WARNING - Retrying (Retry(total=2, connect=None, read=None, redirect=None, status=None)) after connection broken by 'NewConnectionError('<urllib3.connection.HTTPConnection object at 0x00000219F6472F90>: Failed to establish a new connection: [WinError 10061] No connection could be made because the target machine actively refused it')': /session/4fbded65cbaa46c2e9b54babcde4071d/element
2024-06-07 01:59:19,810 - WARNING - Retrying (Retry(total=1, connect=None, read=None, redirect=None, status=None)) after connection broken by 'NewConnectionError('<urllib3.connection.HTTPConnection object at 0x00000219F64737D0>: Failed to establish a new connection: [WinError 10061] No connection could be made because the target machine actively refused it')': /session/4fbded65cbaa46c2e9b54babcde4071d/element
2024-06-07 01:59:23,860 - WARNING - Retrying (Retry(total=0, connect=None, read=None, redirect=None, status=None)) after connection broken by 'NewConnectionError('<urllib3.connection.HTTPConnection object at 0x00000219F64728D0>: Failed to establish a new connection: [WinError 10061] No connection could be made because the target machine actively refused it')': /session/4fbded65cbaa46c2e9b54babcde4071d/element
2024-06-07 01:59:27,963 - INFO - Started Scraping URL -> 2/2
2024-06-07 01:59:32,005 - WARNING - Retrying (Retry(total=2, connect=None, read=None, redirect=None, status=None)) after connection broken by 'NewConnectionError('<urllib3.connection.HTTPConnection object at 0x00000219F6467810>: Failed to establish a new connection: [WinError 10061] No connection could be made because the target machine actively refused it')': /session/4fbded65cbaa46c2e9b54babcde4071d/url
2024-06-07 01:59:36,039 - WARNING - Retrying (Retry(total=1, connect=None, read=None, redirect=None, status=None)) after connection broken by 'NewConnectionError('<urllib3.connection.HTTPConnection object at 0x00000219F64671D0>: Failed to establish a new connection: [WinError 10061] No connection could be made because the target machine actively refused it')': /session/4fbded65cbaa46c2e9b54babcde4071d/url
2024-06-07 01:59:40,509 - WARNING - Retrying (Retry(total=0, connect=None, read=None, redirect=None, status=None)) after connection broken by 'NewConnectionError('<urllib3.connection.HTTPConnection object at 0x00000219F64654D0>: Failed to establish a new connection: [WinError 10061] No connection could be made because the target machine actively refused it')': /session/4fbded65cbaa46c2e9b54babcde4071d/url
2024-06-07 01:59:44,542 - ERROR - Error in => https://escambia.realtaxdeed.com/index.cfm?resetcfcobjs=1 | Error: HTTPConnectionPool(host='localhost', port=63442): Max retries exceeded with url: /session/4fbded65cbaa46c2e9b54babcde4071d/url (Caused by NewConnectionError('<urllib3.connection.HTTPConnection object at 0x00000219F6467910>: Failed to establish a new connection: [WinError 10061] No connection could be made because the target machine actively refused it'))
Traceback (most recent call last):
  File "C:\Users\MAK\Documents\GitHub\scraper_BOT-1_v3\venv\Lib\site-packages\urllib3\connection.py", line 174, in _new_conn
    conn = connection.create_connection(
           ^^^^^^^^^^^^^^^^^^^^^^^^^^^^^
  File "C:\Users\MAK\Documents\GitHub\scraper_BOT-1_v3\venv\Lib\site-packages\urllib3\util\connection.py", line 95, in create_connection
    raise err
  File "C:\Users\MAK\Documents\GitHub\scraper_BOT-1_v3\venv\Lib\site-packages\urllib3\util\connection.py", line 85, in create_connection
    sock.connect(sa)
ConnectionRefusedError: [WinError 10061] No connection could be made because the target machine actively refused it

During handling of the above exception, another exception occurred:

Traceback (most recent call last):
  File "C:\Users\MAK\Documents\GitHub\scraper_BOT-1_v3\venv\Lib\site-packages\urllib3\connectionpool.py", line 715, in urlopen
    httplib_response = self._make_request(
                       ^^^^^^^^^^^^^^^^^^^
  File "C:\Users\MAK\Documents\GitHub\scraper_BOT-1_v3\venv\Lib\site-packages\urllib3\connectionpool.py", line 416, in _make_request
    conn.request(method, url, **httplib_request_kw)
  File "C:\Users\MAK\Documents\GitHub\scraper_BOT-1_v3\venv\Lib\site-packages\urllib3\connection.py", line 244, in request
    super(HTTPConnection, self).request(method, url, body=body, headers=headers)
  File "C:\Users\MAK\AppData\Local\Programs\Python\Python311\Lib\http\client.py", line 1286, in request
    self._send_request(method, url, body, headers, encode_chunked)
  File "C:\Users\MAK\AppData\Local\Programs\Python\Python311\Lib\http\client.py", line 1332, in _send_request
    self.endheaders(body, encode_chunked=encode_chunked)
  File "C:\Users\MAK\AppData\Local\Programs\Python\Python311\Lib\http\client.py", line 1281, in endheaders
    self._send_output(message_body, encode_chunked=encode_chunked)
  File "C:\Users\MAK\AppData\Local\Programs\Python\Python311\Lib\http\client.py", line 1041, in _send_output
    self.send(msg)
  File "C:\Users\MAK\AppData\Local\Programs\Python\Python311\Lib\http\client.py", line 979, in send
    self.connect()
  File "C:\Users\MAK\Documents\GitHub\scraper_BOT-1_v3\venv\Lib\site-packages\urllib3\connection.py", line 205, in connect
    conn = self._new_conn()
           ^^^^^^^^^^^^^^^^
  File "C:\Users\MAK\Documents\GitHub\scraper_BOT-1_v3\venv\Lib\site-packages\urllib3\connection.py", line 186, in _new_conn
    raise NewConnectionError(
urllib3.exceptions.NewConnectionError: <urllib3.connection.HTTPConnection object at 0x00000219F6467910>: Failed to establish a new connection: [WinError 10061] No connection could be made because the target machine actively refused it

During handling of the above exception, another exception occurred:

Traceback (most recent call last):
  File "C:\Users\MAK\Documents\GitHub\scraper_BOT-1_v3\scraper_BOT-1_v3.1.1.1-test.py", line 422, in <module>
    driver.get(data['modified_url'])
  File "C:\Users\MAK\Documents\GitHub\scraper_BOT-1_v3\venv\Lib\site-packages\selenium\webdriver\remote\webdriver.py", line 354, in get
    self.execute(Command.GET, {"url": url})
  File "C:\Users\MAK\Documents\GitHub\scraper_BOT-1_v3\venv\Lib\site-packages\selenium\webdriver\remote\webdriver.py", line 343, in execute
    response = self.command_executor.execute(driver_command, params)
               ^^^^^^^^^^^^^^^^^^^^^^^^^^^^^^^^^^^^^^^^^^^^^^^^^^^^^
  File "C:\Users\MAK\Documents\GitHub\scraper_BOT-1_v3\venv\Lib\site-packages\selenium\webdriver\remote\remote_connection.py", line 291, in execute
    return self._request(command_info[0], url, body=data)
           ^^^^^^^^^^^^^^^^^^^^^^^^^^^^^^^^^^^^^^^^^^^^^^
  File "C:\Users\MAK\Documents\GitHub\scraper_BOT-1_v3\venv\Lib\site-packages\selenium\webdriver\remote\remote_connection.py", line 312, in _request
    response = self._conn.request(method, url, body=body, headers=headers)
               ^^^^^^^^^^^^^^^^^^^^^^^^^^^^^^^^^^^^^^^^^^^^^^^^^^^^^^^^^^^
  File "C:\Users\MAK\Documents\GitHub\scraper_BOT-1_v3\venv\Lib\site-packages\urllib3\request.py", line 81, in request
    return self.request_encode_body(
           ^^^^^^^^^^^^^^^^^^^^^^^^^
  File "C:\Users\MAK\Documents\GitHub\scraper_BOT-1_v3\venv\Lib\site-packages\urllib3\request.py", line 173, in request_encode_body
    return self.urlopen(method, url, **extra_kw)
           ^^^^^^^^^^^^^^^^^^^^^^^^^^^^^^^^^^^^^
  File "C:\Users\MAK\Documents\GitHub\scraper_BOT-1_v3\venv\Lib\site-packages\urllib3\poolmanager.py", line 376, in urlopen
    response = conn.urlopen(method, u.request_uri, **kw)
               ^^^^^^^^^^^^^^^^^^^^^^^^^^^^^^^^^^^^^^^^^
  File "C:\Users\MAK\Documents\GitHub\scraper_BOT-1_v3\venv\Lib\site-packages\urllib3\connectionpool.py", line 827, in urlopen
    return self.urlopen(
           ^^^^^^^^^^^^^
  File "C:\Users\MAK\Documents\GitHub\scraper_BOT-1_v3\venv\Lib\site-packages\urllib3\connectionpool.py", line 827, in urlopen
    return self.urlopen(
           ^^^^^^^^^^^^^
  File "C:\Users\MAK\Documents\GitHub\scraper_BOT-1_v3\venv\Lib\site-packages\urllib3\connectionpool.py", line 827, in urlopen
    return self.urlopen(
           ^^^^^^^^^^^^^
  File "C:\Users\MAK\Documents\GitHub\scraper_BOT-1_v3\venv\Lib\site-packages\urllib3\connectionpool.py", line 799, in urlopen
    retries = retries.increment(
              ^^^^^^^^^^^^^^^^^^
  File "C:\Users\MAK\Documents\GitHub\scraper_BOT-1_v3\venv\Lib\site-packages\urllib3\util\retry.py", line 592, in increment
    raise MaxRetryError(_pool, url, error or ResponseError(cause))
urllib3.exceptions.MaxRetryError: HTTPConnectionPool(host='localhost', port=63442): Max retries exceeded with url: /session/4fbded65cbaa46c2e9b54babcde4071d/url (Caused by NewConnectionError('<urllib3.connection.HTTPConnection object at 0x00000219F6467910>: Failed to establish a new connection: [WinError 10061] No connection could be made because the target machine actively refused it'))
